<?xml version="1.0" ?>
<!-- =================================================================================== -->
<!-- |    This document was autogenerated by xacro from /home/frank/dancerobot_ws/src/mobilehri2023/chair_dance_sim/urdf/chair_robot.urdf.xacro | -->
<!-- |    EDITING THIS FILE BY HAND IS NOT RECOMMENDED                                 | -->
<!-- =================================================================================== -->
<!--
  Dancing Chair Robot — URDF (xacro)

  Physical design:
    A foldable metal chair with two powered wheels attached to the back legs.
    Front legs rest on small caster spheres for stability.

  Kinematics: Differential drive (two back wheels)

  Coordinate frame:
    x = forward (towards front legs)
    z = up
    Origin at center of seat underside

  Key dimensions (meters):
    Seat:     0.40 wide × 0.40 deep × 0.02 thick
    Backrest: 0.40 wide × 0.35 tall × 0.02 thick, tilted 10° back
    Legs:     0.025 radius × 0.45 long (steel tube)
    Wheels:   0.075 radius × 0.03 wide
    Track:    0.45 m (center-to-center of back wheels)
-->
<robot name="chair_robot">
  <!-- ══════════════════════════════════════════════════════════════════════
       Macros
       ══════════════════════════════════════════════════════════════════════ -->
  <!-- ══════════════════════════════════════════════════════════════════════
       Robot Structure
       ══════════════════════════════════════════════════════════════════════ -->
  <!-- base_footprint: on the ground plane, used by nav -->
  <link name="base_footprint"/>
  <!-- base_link: at wheel axle height -->
  <link name="base_link">
    <inertial>
      <mass value="0.01"/>
      <inertia ixx="0.001" ixy="0" ixz="0" iyy="0.001" iyz="0" izz="0.001"/>
    </inertial>
  </link>
  <joint name="base_footprint_joint" type="fixed">
    <parent link="base_footprint"/>
    <child link="base_link"/>
    <origin rpy="0 0 0" xyz="0 0 0.075"/>
  </joint>
  <!-- ── Seat ─────────────────────────────────────────────────────────── -->
  <link name="seat">
    <visual>
      <geometry>
        <box size="0.4 0.4 0.02"/>
      </geometry>
      <material name="chair_mat">
        <color rgba="0.15 0.15 0.15 1.0"/>
      </material>
    </visual>
    <collision>
      <geometry>
        <box size="0.4 0.4 0.02"/>
      </geometry>
    </collision>
    <inertial>
      <mass value="2.0"/>
      <inertia ixx="0.02673333333333334" ixy="0" ixz="0" iyy="0.02673333333333334" iyz="0" izz="0.053333333333333344"/>
    </inertial>
  </link>
  <joint name="seat_joint" type="fixed">
    <parent link="base_link"/>
    <child link="seat"/>
    <!-- Seat is above the wheel axle. Back legs are at the rear of the seat. -->
    <origin rpy="0 0 0" xyz="0.1 0 0.385"/>
  </joint>
  <!-- ── Backrest ─────────────────────────────────────────────────────── -->
  <link name="backrest">
    <visual>
      <geometry>
        <box size="0.02 0.4 0.35"/>
      </geometry>
      <material name="chair_mat">
        <color rgba="0.15 0.15 0.15 1.0"/>
      </material>
    </visual>
    <collision>
      <geometry>
        <box size="0.02 0.4 0.35"/>
      </geometry>
    </collision>
    <inertial>
      <mass value="1.5"/>
      <inertia ixx="0.035312500000000004" ixy="0" ixz="0" iyy="0.015362499999999996" iyz="0" izz="0.020050000000000005"/>
    </inertial>
  </link>
  <joint name="backrest_joint" type="fixed">
    <parent link="seat"/>
    <child link="backrest"/>
    <!-- Backrest rises from the back edge of the seat, tilted slightly back -->
    <origin rpy="0 -0.1745327777777778 0" xyz="-0.19 0 0.185"/>
  </joint>
  <link name="back_left_leg">
    <visual>
      <geometry>
        <cylinder length="0.45" radius="0.025"/>
      </geometry>
      <material name="chair_mat">
        <color rgba="0.15 0.15 0.15 1.0"/>
      </material>
    </visual>
    <collision>
      <geometry>
        <cylinder length="0.45" radius="0.025"/>
      </geometry>
    </collision>
    <inertial>
      <mass value="0.3"/>
      <inertia ixx="0.005109375" ixy="0" ixz="0" iyy="0.005109375" iyz="0" izz="9.375e-05"/>
    </inertial>
  </link>
  <joint name="back_left_leg_joint" type="fixed">
    <parent link="seat"/>
    <child link="back_left_leg"/>
    <origin rpy="0 0 0" xyz="-0.17500000000000002 0.17500000000000002 -0.225"/>
  </joint>
  <link name="back_right_leg">
    <visual>
      <geometry>
        <cylinder length="0.45" radius="0.025"/>
      </geometry>
      <material name="chair_mat">
        <color rgba="0.15 0.15 0.15 1.0"/>
      </material>
    </visual>
    <collision>
      <geometry>
        <cylinder length="0.45" radius="0.025"/>
      </geometry>
    </collision>
    <inertial>
      <mass value="0.3"/>
      <inertia ixx="0.005109375" ixy="0" ixz="0" iyy="0.005109375" iyz="0" izz="9.375e-05"/>
    </inertial>
  </link>
  <joint name="back_right_leg_joint" type="fixed">
    <parent link="seat"/>
    <child link="back_right_leg"/>
    <origin rpy="0 0 0" xyz="-0.17500000000000002 -0.17500000000000002 -0.225"/>
  </joint>
  <link name="back_left_wheel">
    <visual>
      <geometry>
        <cylinder length="0.03" radius="0.075"/>
      </geometry>
      <origin rpy="0 0 0" xyz="0 0 0"/>
      <material name="wheel_mat">
        <color rgba="0.3 0.3 0.3 1.0"/>
      </material>
    </visual>
    <collision>
      <geometry>
        <cylinder length="0.03" radius="0.075"/>
      </geometry>
    </collision>
    <inertial>
      <mass value="0.5"/>
      <inertia ixx="0.000740625" ixy="0" ixz="0" iyy="0.000740625" iyz="0" izz="0.00140625"/>
    </inertial>
  </link>
  <joint name="back_left_wheel_joint" type="continuous">
    <parent link="back_left_leg"/>
    <child link="back_left_wheel"/>
    <!-- Wheel sits at bottom of back leg, offset outward -->
    <origin rpy="-1.5708 0 0" xyz="0 0.045 -0.225"/>
    <axis xyz="0 0 1"/>
    <dynamics damping="0.1" friction="0.05"/>
  </joint>
  <link name="back_right_wheel">
    <visual>
      <geometry>
        <cylinder length="0.03" radius="0.075"/>
      </geometry>
      <origin rpy="0 0 0" xyz="0 0 0"/>
      <material name="wheel_mat">
        <color rgba="0.3 0.3 0.3 1.0"/>
      </material>
    </visual>
    <collision>
      <geometry>
        <cylinder length="0.03" radius="0.075"/>
      </geometry>
    </collision>
    <inertial>
      <mass value="0.5"/>
      <inertia ixx="0.000740625" ixy="0" ixz="0" iyy="0.000740625" iyz="0" izz="0.00140625"/>
    </inertial>
  </link>
  <joint name="back_right_wheel_joint" type="continuous">
    <parent link="back_right_leg"/>
    <child link="back_right_wheel"/>
    <!-- Wheel sits at bottom of back leg, offset outward -->
    <origin rpy="-1.5708 0 0" xyz="0 -0.045 -0.225"/>
    <axis xyz="0 0 1"/>
    <dynamics damping="0.1" friction="0.05"/>
  </joint>
  <link name="front_left_leg">
    <visual>
      <geometry>
        <cylinder length="0.45" radius="0.025"/>
      </geometry>
      <material name="chair_mat">
        <color rgba="0.15 0.15 0.15 1.0"/>
      </material>
    </visual>
    <collision>
      <geometry>
        <cylinder length="0.45" radius="0.025"/>
      </geometry>
    </collision>
    <inertial>
      <mass value="0.3"/>
      <inertia ixx="0.005109375" ixy="0" ixz="0" iyy="0.005109375" iyz="0" izz="9.375e-05"/>
    </inertial>
  </link>
  <joint name="front_left_leg_joint" type="fixed">
    <parent link="seat"/>
    <child link="front_left_leg"/>
    <origin rpy="0 0 0" xyz="0.17500000000000002 0.17500000000000002 -0.225"/>
  </joint>
  <link name="front_right_leg">
    <visual>
      <geometry>
        <cylinder length="0.45" radius="0.025"/>
      </geometry>
      <material name="chair_mat">
        <color rgba="0.15 0.15 0.15 1.0"/>
      </material>
    </visual>
    <collision>
      <geometry>
        <cylinder length="0.45" radius="0.025"/>
      </geometry>
    </collision>
    <inertial>
      <mass value="0.3"/>
      <inertia ixx="0.005109375" ixy="0" ixz="0" iyy="0.005109375" iyz="0" izz="9.375e-05"/>
    </inertial>
  </link>
  <joint name="front_right_leg_joint" type="fixed">
    <parent link="seat"/>
    <child link="front_right_leg"/>
    <origin rpy="0 0 0" xyz="0.17500000000000002 -0.17500000000000002 -0.225"/>
  </joint>
  <link name="front_left_caster">
    <visual>
      <geometry>
        <sphere radius="0.02"/>
      </geometry>
      <material name="caster_mat">
        <color rgba="0.5 0.5 0.5 1.0"/>
      </material>
    </visual>
    <collision>
      <geometry>
        <sphere radius="0.02"/>
      </geometry>
      <surface>
        <friction>
          <ode>
            <mu>0.001</mu>
            <mu2>0.001</mu2>
          </ode>
        </friction>
      </surface>
    </collision>
    <inertial>
      <mass value="0.1"/>
      <inertia ixx="1.6000000000000003e-05" ixy="0" ixz="0" iyy="1.6000000000000003e-05" iyz="0" izz="1.6000000000000003e-05"/>
    </inertial>
  </link>
  <joint name="front_left_caster_joint" type="fixed">
    <parent link="front_left_leg"/>
    <child link="front_left_caster"/>
    <origin rpy="0 0 0" xyz="0 0 -0.24"/>
  </joint>
  <link name="front_right_caster">
    <visual>
      <geometry>
        <sphere radius="0.02"/>
      </geometry>
      <material name="caster_mat">
        <color rgba="0.5 0.5 0.5 1.0"/>
      </material>
    </visual>
    <collision>
      <geometry>
        <sphere radius="0.02"/>
      </geometry>
      <surface>
        <friction>
          <ode>
            <mu>0.001</mu>
            <mu2>0.001</mu2>
          </ode>
        </friction>
      </surface>
    </collision>
    <inertial>
      <mass value="0.1"/>
      <inertia ixx="1.6000000000000003e-05" ixy="0" ixz="0" iyy="1.6000000000000003e-05" iyz="0" izz="1.6000000000000003e-05"/>
    </inertial>
  </link>
  <joint name="front_right_caster_joint" type="fixed">
    <parent link="front_right_leg"/>
    <child link="front_right_caster"/>
    <origin rpy="0 0 0" xyz="0 0 -0.24"/>
  </joint>
  <!-- ══════════════════════════════════════════════════════════════════════
       Gz Sim (Fortress) Plugins
       ══════════════════════════════════════════════════════════════════════ -->
  <gazebo>
    <!-- Differential drive controller (Gz Sim system plugin) -->
    <plugin filename="gz-sim-diff-drive-system" name="gz::sim::systems::DiffDrive">
      <left_joint>back_left_wheel_joint</left_joint>
      <right_joint>back_right_wheel_joint</right_joint>
      <wheel_separation>0.45</wheel_separation>
      <wheel_radius>0.075</wheel_radius>
      <max_linear_acceleration>2.0</max_linear_acceleration>
      <odom_publish_frequency>50</odom_publish_frequency>
      <topic>cmd_vel</topic>
      <odom_topic>odom</odom_topic>
      <tf_topic>tf</tf_topic>
      <frame_id>odom</frame_id>
      <child_frame_id>base_footprint</child_frame_id>
    </plugin>
    <!-- Joint state publisher for RViz -->
    <plugin filename="gz-sim-joint-state-publisher-system" name="gz::sim::systems::JointStatePublisher">
      <joint_name>back_left_wheel_joint</joint_name>
      <joint_name>back_right_wheel_joint</joint_name>
      <update_rate>50</update_rate>
      <topic>joint_states</topic>
    </plugin>
  </gazebo>
  <!-- Wheel surface properties for good traction -->
  <gazebo reference="back_left_wheel">
    <mu1>1.5</mu1>
    <mu2>1.5</mu2>
  </gazebo>
  <gazebo reference="back_right_wheel">
    <mu1>1.5</mu1>
    <mu2>1.5</mu2>
  </gazebo>
  <!-- Low friction on casters -->
  <gazebo reference="front_left_caster">
    <mu1>0.001</mu1>
    <mu2>0.001</mu2>
  </gazebo>
  <gazebo reference="front_right_caster">
    <mu1>0.001</mu1>
    <mu2>0.001</mu2>
  </gazebo>
</robot>
